<?xml version="1.0" ?>
<!-- =================================================================================== -->
<!-- |    This document was autogenerated by xacro from robot.urdf.xacro               | -->
<!-- |    EDITING THIS FILE BY HAND IS NOT RECOMMENDED                                 | -->
<!-- =================================================================================== -->
<robot name="robot">
  <!-- <xacro:if value="$(arg simulation)">
    <xacro:include filename="$(find smb_description)/urdf/smb_gazebo_addins.urdf.xacro"/>
  </xacro:if> -->
  <!-- Materials -->
  <material name="black">
    <color rgba="0 0 0 1.0"/>
  </material>
  <material name="dark_grey">
    <color rgba="0 0 0 0.6078431372549019 1.0"/>
  </material>
  <material name="blue">
    <color rgba="0 0 0.7843137254901961 1.0"/>
  </material>
  <material name="green">
    <color rgba="0 0.7843137254901961 0 1.0"/>
  </material>
  <material name="grey">
    <color rgba="0.19607843137254902 0.19607843137254902 0.19607843137254902 1.0"/>
  </material>
  <material name="orange">
    <color rgba="1.0 0.4235294117647059 0.0392156862745098 1.0"/>
  </material>
  <material name="brown">
    <color rgba="0.8705882352941177 0.8117647058823529 0.7647058823529411 1.0"/>
  </material>
  <material name="red">
    <color rgba="0.7843137254901961 0 0 1.0"/>
  </material>
  <material name="white">
    <color rgba="1.0 1.0 1.0 1.0"/>
  </material>
  <link name="base_link">
    <collision>
      <origin rpy="0 0 0" xyz="0 0 0"/>
      <geometry>
        <box size="0.605 0.41 0.197"/>
      </geometry>
    </collision>
    <visual>
      <origin rpy="0 0 0" xyz="0 0 0"/>
      <geometry>
        <box size="0.605 0.41 0.197"/>
      </geometry>
      <material name="base_material">
        <color rgba="0.8 0.0 0.1 1.0"/>
      </material>
    </visual>
  </link>
  <joint name="base_footprint_to_base_link" type="fixed">
    <parent link="base_link"/>
    <child link="base_footprint"/>
    <origin rpy="0 0 0" xyz="0 0 0"/>
  </joint>
  <link name="base_footprint">
    <inertial>
      <origin rpy="0 0 0" xyz="0 0 0"/>
      <mass value="0.1"/>
      <inertia ixx="0.6896966666666665" ixy="0" ixz="0" iyy="1.3494466666666665" iyz="0" izz="1.3494466666666665"/>
    </inertial>
    <visual>
      <origin rpy="0 0 0" xyz="0 0 0"/>
      <geometry>
        <box size="0.1 0.1 0.1"/>
      </geometry>
      <material name="base_material">
        <color rgba="0.8 0.0 0.1 1.0"/>
      </material>
    </visual>
  </link>
  <link name="top">
    <collision>
      <origin rpy="0 0 0" xyz="-0.07 0 0"/>
      <geometry>
        <mesh filename="/home/perfrivik/rss_ws/install/smb_description/share/smb_description/urdf/meshes/SMB_step.dae"/>
      </geometry>
    </collision>
    <visual>
      <origin rpy="0 0 0" xyz="0 0 0"/>
      <geometry>
        <mesh filename="/home/perfrivik/rss_ws/install/smb_description/share/smb_description/urdf/meshes/SMB_step.dae"/>
      </geometry>
    </visual>
  </link>
  <gazebo reference="top">
    <material>Gazebo/Grey</material>
  </gazebo>
  <gazebo reference="base_link">
    <material>Gazebo/Red</material>
  </gazebo>
  <joint name="top_to_base_link" type="fixed">
    <parent link="base_link"/>
    <child link="top"/>
    <!-- <origin xyz="${topXOffset/2.0} 0.0 ${chassisHeight/2.0 + topHeight/2.0}" rpy="0 0 0"/> -->
    <origin rpy="0 0 0" xyz="0.0 0.0 0.0985"/>
  </joint>
  <!-- Fixed joint to add dummy inertia link -->
  <joint name="base_to_base_inertia" type="fixed">
    <parent link="base_link"/>
    <child link="base_inertia"/>
    <origin rpy="0 0 0" xyz="0 0 0"/>
  </joint>
  <!-- Dummy inertia link, because KDL cannot have inertia on the base link -->
  <link name="base_inertia">
    <inertial>
      <origin rpy="0 0 0" xyz="0 0 0"/>
      <mass value="40"/>
      <inertia ixx="0.6896966666666665" ixy="0" ixz="0" iyy="1.3494466666666665" iyz="0" izz="1.3494466666666665"/>
    </inertial>
  </link>
  <joint name="LF_WHEEL_JOINT" type="continuous">
    <parent link="base_link"/>
    <child link="LF_WHEEL"/>
    <origin rpy="-1.5707963267948966 0 0" xyz="0.2159 0.285 -0.018500000000000003"/>
    <axis rpy="0 0 0" xyz="0 0 1"/>
    <dynamics damping="1.0" friction="0.0"/>
    <limit effort="100" velocity="10"/>
    <joint_properties damping="0.2" friction="0.2"/>
  </joint>
  <link name="LF_WHEEL">
    <collision>
      <origin rpy="0 0 0" xyz="0 0 0"/>
      <geometry>
        <cylinder length="0.01" radius="0.19"/>
      </geometry>
    </collision>
    <visual>
      <origin rpy="1.570796 0  0" xyz="0 0 0"/>
      <geometry>
        <mesh filename="/home/perfrivik/rss_ws/install/smb_description/share/smb_description/urdf/meshes/wheel.dae"/>
      </geometry>
    </visual>
    <inertial>
      <origin rpy="0 0 0" xyz="0 0 0"/>
      <mass value="5"/>
      <inertia ixx="0.04929166666666668" ixy="0" ixz="0" iyy="0.04929166666666668" iyz="0" izz="0.09025"/>
    </inertial>
  </link>
  <joint name="RF_WHEEL_JOINT" type="continuous">
    <parent link="base_link"/>
    <child link="RF_WHEEL"/>
    <origin rpy="-1.5707963267948966 0 0" xyz="0.2159 -0.285 -0.018500000000000003"/>
    <axis rpy="0 0 0" xyz="0 0 1"/>
    <dynamics damping="1.0" friction="0.0"/>
    <limit effort="100" velocity="10"/>
    <joint_properties damping="0.2" friction="0.2"/>
  </joint>
  <link name="RF_WHEEL">
    <collision>
      <origin rpy="0 0 0" xyz="0 0 0"/>
      <geometry>
        <cylinder length="0.01" radius="0.19"/>
      </geometry>
    </collision>
    <visual>
      <origin rpy="1.570796 0  0" xyz="0 0 0"/>
      <geometry>
        <mesh filename="/home/perfrivik/rss_ws/install/smb_description/share/smb_description/urdf/meshes/wheel.dae"/>
      </geometry>
    </visual>
    <inertial>
      <origin rpy="0 0 0" xyz="0 0 0"/>
      <mass value="5"/>
      <inertia ixx="0.04929166666666668" ixy="0" ixz="0" iyy="0.04929166666666668" iyz="0" izz="0.09025"/>
    </inertial>
  </link>
  <joint name="LH_WHEEL_JOINT" type="continuous">
    <parent link="base_link"/>
    <child link="LH_WHEEL"/>
    <origin rpy="-1.5707963267948966 0 0" xyz="-0.2159 0.285 -0.018500000000000003"/>
    <axis rpy="0 0 0" xyz="0 0 1"/>
    <dynamics damping="1.0" friction="0.0"/>
    <limit effort="100" velocity="10"/>
    <joint_properties damping="0.2" friction="0.2"/>
  </joint>
  <link name="LH_WHEEL">
    <collision>
      <origin rpy="0 0 0" xyz="0 0 0"/>
      <geometry>
        <cylinder length="0.01" radius="0.19"/>
      </geometry>
    </collision>
    <visual>
      <origin rpy="1.570796 0  0" xyz="0 0 0"/>
      <geometry>
        <mesh filename="/home/perfrivik/rss_ws/install/smb_description/share/smb_description/urdf/meshes/wheel.dae"/>
      </geometry>
    </visual>
    <inertial>
      <origin rpy="0 0 0" xyz="0 0 0"/>
      <mass value="5"/>
      <inertia ixx="0.04929166666666668" ixy="0" ixz="0" iyy="0.04929166666666668" iyz="0" izz="0.09025"/>
    </inertial>
  </link>
  <joint name="RH_WHEEL_JOINT" type="continuous">
    <parent link="base_link"/>
    <child link="RH_WHEEL"/>
    <origin rpy="-1.5707963267948966 0 0" xyz="-0.2159 -0.285 -0.018500000000000003"/>
    <axis rpy="0 0 0" xyz="0 0 1"/>
    <dynamics damping="1.0" friction="0.0"/>
    <limit effort="100" velocity="10"/>
    <joint_properties damping="0.2" friction="0.2"/>
  </joint>
  <link name="RH_WHEEL">
    <collision>
      <origin rpy="0 0 0" xyz="0 0 0"/>
      <geometry>
        <cylinder length="0.01" radius="0.19"/>
      </geometry>
    </collision>
    <visual>
      <origin rpy="1.570796 0  0" xyz="0 0 0"/>
      <geometry>
        <mesh filename="/home/perfrivik/rss_ws/install/smb_description/share/smb_description/urdf/meshes/wheel.dae"/>
      </geometry>
    </visual>
    <inertial>
      <origin rpy="0 0 0" xyz="0 0 0"/>
      <mass value="5"/>
      <inertia ixx="0.04929166666666668" ixy="0" ixz="0" iyy="0.04929166666666668" iyz="0" izz="0.09025"/>
    </inertial>
  </link>
  <gazebo>
    <plugin filename="gz-sim-imu-system" name="gz::sim::systems::Imu">
        </plugin>
  </gazebo>
  <gazebo reference="imu_link">
    <sensor name="imu_sensor" type="imu">
      <always_on>true</always_on>
      <update_rate>400</update_rate>
      <visualize>true</visualize>
      <topic>/imu</topic>
      <!-- <plugin name="smb_imu_plugin" filename="libgazebo_ros_imu_sensor.so">
          <ros>
            <namespace>/</namespace>
            <remapping>~/out:=${imu_topic}</remapping>
          </ros>
          <initial_orientation_as_reference>false</initial_orientation_as_reference>
        </plugin> -->
    </sensor>
  </gazebo>
  <!-- IMU joint and link definitions remain the same -->
  <joint name="imu_joint" type="fixed">
    <origin rpy="0 0 0" xyz="0.2554 -0.02397 0.1795"/>
    <parent link="base_link"/>
    <child link="imu_link"/>
  </joint>
  <link name="imu_link">
    <inertial>
      <mass value="0.001"/>
      <origin rpy="0 0 0" xyz="0 0 0"/>
      <inertia ixx="0.0001" ixy="0" ixz="0" iyy="0.000001" iyz="0" izz="0.0001"/>
    </inertial>
    <visual>
      <origin rpy="0 0 0" xyz="0 0 0"/>
      <geometry>
        <mesh filename="/home/perfrivik/rss_ws/install/smb_description/share/smb_description/urdf/meshes/SMB_imu.dae"/>
      </geometry>
    </visual>
    <collision>
      <origin rpy="0 0 0" xyz="0 0 0"/>
      <geometry>
        <mesh filename="/home/perfrivik/rss_ws/install/smb_description/share/smb_description/urdf/meshes/SMB_imu.dae"/>
      </geometry>
    </collision>
  </link>
  <link name="imu">
    <inertial>
      <mass value="0.001"/>
      <origin rpy="0 0 0" xyz="0 0 0"/>
      <inertia ixx="0.0001" ixy="0" ixz="0" iyy="0.000001" iyz="0" izz="0.0001"/>
    </inertial>
  </link>
  <joint name="imu_imu_link_joint" type="fixed">
    <origin rpy="0 0 0" xyz="0 0 0"/>
    <parent link="imu_link"/>
    <child link="imu"/>
  </joint>
  <gazebo reference="imu_link">
    <material>Gazebo/Orange</material>
  </gazebo>
  <gazebo reference="imu_joint">
    <disableFixedJointLumping>true</disableFixedJointLumping>
  </gazebo>
  <link name="rgb_camera_link">
    <inertial>
      <mass value="0.01"/>
      <!-- [kg] -->
      <inertia ixx="1e-5" ixy="0" ixz="0" iyy="1e-5" iyz="0" izz="1e-5"/>
    </inertial>
    <visual>
      <geometry>
        <mesh filename="/home/perfrivik/rss_ws/install/smb_description/share/smb_description/urdf/meshes/SMB_blackfly_camera.dae"/>
      </geometry>
    </visual>
    <collision>
      <geometry>
        <mesh filename="/home/perfrivik/rss_ws/install/smb_description/share/smb_description/urdf/meshes/SMB_blackfly_camera.dae"/>
      </geometry>
    </collision>
    <material name="red">
      <color rgba="255 0 10 255"/>
    </material>
  </link>
  <gazebo reference="rgb_camera_link">
    <material>Gazebo/Red</material>
  </gazebo>
  <joint name="rgb_camera_camera_joint" type="fixed">
    <!-- <origin xyz="${rgb_camera_origin_xyz}" rpy="${rgb_camera_origin_rpy}"/> -->
    <origin rpy="0 0 0" xyz="0.29082 -0.04542 0.194"/>
    <parent link="base_link"/>
    <child link="rgb_camera_link"/>
  </joint>
  <gazebo reference="rgb_camera_camera_joint">
    <disableFixedJointLumping>true</disableFixedJointLumping>
  </gazebo>
  <link name="rgb_camera_optical_link"/>
  <joint name="rgb_camera_camera_optical_joint" type="fixed">
    <origin rpy="-1.57 0 -1.57" xyz="0.0066 0 0"/>
    <parent link="rgb_camera_link"/>
    <child link="rgb_camera_optical_link"/>
  </joint>
  <!-- <gazebo> -->
  <!-- <plugin
      filename="gz-sim-physics-system"
      name="gz::sim::systems::Physics">
    </plugin> -->
  <!-- <plugin
      filename="gz-sim-sensors-system"
      name="gz::sim::systems::Sensors">
      <render_engine>ogre2</render_engine>
    </plugin> -->
  <!-- <plugin
      filename="gz-sim-user-commands-system"
      name="gz::sim::systems::UserCommands">
    </plugin>
    <plugin
      filename="gz-sim-scene-broadcaster-system"
      name="gz::sim::systems::SceneBroadcaster">
    </plugin> -->
  <!-- </gazebo> -->
  <gazebo reference="rgb_camera_link">
    <sensor name="camera" type="camera">
      <camera>
        <horizontal_fov>1.047</horizontal_fov>
        <image>
          <width>320</width>
          <height>240</height>
        </image>
        <clip>
          <near>0.1</near>
          <far>100</far>
        </clip>
      </camera>
      <always_on>1</always_on>
      <update_rate>30</update_rate>
      <visualize>true</visualize>
      <topic>camera</topic>
    </sensor>
    <!-- <sensor type="camera" name="${name}">
        <pose>0.0066 0 0 0 0 0</pose>
        <visualize>false</visualize>
        <update_rate>${rate}</update_rate>
        <camera>
          <horizontal_fov>1.192</horizontal_fov>
          <image>
            <width>1440</width>
            <height>1080</height>
            <format>R8G8B8</format>
          </image>
          <clip>
            <near>0.01</near>
            <far>100</far>
          </clip>
          <noise>
            <type>gaussian</type>
            <mean>0.0</mean>
            <stddev>0.007</stddev>
          </noise>
        </camera>
        <plugin name="gazebo_ros_camera_controller" filename="libgazebo_ros_camera.so">
          <alwaysOn>true</alwaysOn>
          <updateRate>0.0</updateRate>
          <cameraName>${name}</cameraName>
          <imageTopicName>${camera_topic}</imageTopicName>
          <cameraInfoTopicName>${camera_info_topic}</cameraInfoTopicName>
          <frameName>${name}_optical_link</frameName>
          <hackBaseline>0.07</hackBaseline>
          <distortionK1>0.0</distortionK1>
          <distortionK2>0.0</distortionK2>
          <distortionK3>0.0</distortionK3>
          <distortionT1>0.0</distortionT1>
          <distortionT2>0.0</distortionT2>
        </plugin>
      </sensor> -->
  </gazebo>
  <!-- </xacro:if> -->
  <link name="lidar_mount_link">
    <visual>
      <geometry>
        <mesh filename="/home/perfrivik/rss_ws/install/smb_description/share/smb_description/urdf/meshes/LidarBoxV2.dae"/>
      </geometry>
    </visual>
    <inertial>
      <origin rpy="0 0 0" xyz="0 0 0"/>
      <mass value="1e-4"/>
      <inertia ixx="3.3333333333333334e-13" ixy="0" ixz="0" iyy="3.3333333333333334e-13" iyz="0" izz="5e-13"/>
    </inertial>
  </link>
  <gazebo reference="lidar_mount_link">
    <material>Gazebo/Grey</material>
  </gazebo>
  <joint name="lidar_mount_joint" type="fixed">
    <origin rpy="0 0 0" xyz="0.0245 0 0.3265"/>
    <parent link="base_link"/>
    <child link="lidar_mount_link"/>
  </joint>
  <!-- Replacing RS-16 with the default Gazebo lidar -->
  <link name="rslidar">
    <inertial>
      <mass value="0.01"/>
      <origin xyz="0 0 0"/>
      <inertia ixx="1e-7" ixy="0" ixz="0" iyy="1e-7" iyz="0" izz="1e-7"/>
    </inertial>
    <visual>
      <origin rpy="0 0 0" xyz="0 0 0"/>
      <geometry>
        <cylinder length="0.08" radius="0.05"/>
      </geometry>
      <material name="Cyan">
        <color rgba="0 1.0 1.0 1.0"/>
      </material>
    </visual>
  </link>
  <joint name="lidar_mount_link_to_rslidar" type="fixed">
    <parent link="lidar_mount_link"/>
    <child link="rslidar"/>
    <origin rpy="0 0 0" xyz="0.0 0.0 0.139"/>
  </joint>
  <gazebo>
    <plugin filename="gz-sim-sensors-system" name="gz::sim::systems::Sensors">
      <render_engine>ogre2</render_engine>
    </plugin>
  </gazebo>
  <gazebo reference="rslidar">
    <sensor name="rslidar" type="gpu_lidar">
      <gz_frame_id>rslidar</gz_frame_id>
      <topic>scan</topic>
      <update_rate>10</update_rate>
      <lidar>
        <scan>
          <horizontal>
            <samples>440</samples>
            <resolution>1</resolution>
            <min_angle>-3.14</min_angle>
            <max_angle>3.14</max_angle>
          </horizontal>
          <vertical>
            <samples>440</samples>
            <resolution>1</resolution>
            <min_angle>-0.2617993877991494</min_angle>
            <max_angle> 0.2617993877991494</max_angle>
          </vertical>
        </scan>
        <range>
          <min>0.2</min>
          <max>70.0</max>
          <resolution>0.01</resolution>
        </range>
        <frame_id>/rslidar</frame_id>
      </lidar>
      <alwaysOn>ture</alwaysOn>
      <visualize>true</visualize>
    </sensor>
  </gazebo>
  <!-- <xacro:if value="$(arg use_ros2_control)"> -->
  <!-- <xacro:include filename="/home/perfrivik/rss_ws/src/smb/description/ros2_control.xacro" /> -->
  <!-- </xacro:if> -->
  <!-- <xacro:unless value="$(arg use_ros2_control)">
        <xacro:include filename="gazebo_control.xacro" />
    </xacro:unless> -->
  <!-- <xacro:include filename="lidar.xacro" />
    <xacro:include filename="camera.xacro" /> -->
  <!-- <xacro:include filename="depth_camera.xacro" /> -->
  <!-- <xacro:include filename="face.xacro" /> -->
</robot>
